Workbook

Sheet loans_pred_opti_data
B1: lassoret_PESS | C1: std_PESS | D1: funded_amnt | E1: grade | F1: int_rate | G1: default | H1: total_pymnt | I1: recoveries
A2: 75948 | B2: 0.022075878 | C2: 0.081509172 | D2: 10000 | E2: A | F2: 6.62 | G2: 0 | H2: 11002.25 | I2: 0
A3: 42073 | B3: 0.0091794397 | C3: 0.084798681 | D3: 21000 | E3: C | F3: 15.88 | G3: 0 | H3: 25863.48 | I3: 0
A4: 124338 | B4: -0.0038953909 | C4: 0.084798681 | D4: 18825 | E4: C | F4: 16.29 | G4: 1 | H4: 15017.52 | I4: 1668.62
A5: 77394 | B5: 0.029932261 | C5: 0.074974239 | D5: 10000 | E5: D | F5: 18.49 | G5: 0 | H5: 13103.487 | I5: 0
A6: 128896 | B6: 0.0074171234 | C6: 0.081509172 | D6: 4000 | E6: A | F6: 7.62 | G6: 1 | H6: 615.82 | I6: 212.32
A7: 111753 | B7: 0.035854309 | C7: 0.084798681 | D7: 30225 | E7: D | F7: 19.72 | G7: 1 | H7: 6065.72 | I7: 1590.92
A8: 133312 | B8: 0.035843911 | C8: 0.081509172 | D8: 5200 | E8: C | F8: 13.99 | G8: 0 | H8: 6354.947 | I8: 0
A9: 74862 | B9: 0.030216831 | C9: 0.074974239 | D9: 12000 | E9: A | F9: 8.9 | G9: 0 | H9: 13717.38 | I9: 0
A10: 122169 | B10: 0.026192366 | C10: 0.074974239 | D10: 5000 | E10: A | F10: 7.9 | G10: 0 | H10: 5632.21 | I10: 0
A11: 118502 | B11: 0.017208772 | C11: 0.074974239 | D11: 11125 | E11: A | F11: 7.62 | G11: 0 | H11: 12480.627 | I11: 0
A12: 98404 | B12: 0.027467878 | C12: 0.081509172 | D12: 20000 | E12: B | F12: 13.11 | G12: 0 | H12: 22865.987 | I12: 0
A13: 139024 | B13: 0.037196111 | C13: 0.084798681 | D13: 22000 | E13: C | F13: 15.81 | G13: 0 | H13: 26337.7 | I13: 0
... A2001: 23302 | B2001: 0.021300844 | C2001: 0.074974239 | D2001: 13500 | E2001: A | F2001: 6.97 | G2001: 0 | H2001: 14194.332 | I2001: 0

Sheet ret_PESS
A1: Select? (0/1 Vars) | B1: Revenue Per Loan | C1: Markowitz Coefficient | E1: Simple Knapsack Model
A2: 0 | B2: =loans_pred_opti_data!D2*loans_pred_opti_data!B2 -> 220.75878 | C2: =(loans_pred_opti_data!B2-ret_PESS!$G$35*loans_pred_opti_data!C2)*loans_pred_opti_data!D2 -> 139.24961
A3: 0 | B3: =loans_pred_opti_data!D3*loans_pred_opti_data!B3 -> 192.76823 | C3: =(loans_pred_opti_data!B3-ret_PESS!$G$35*loans_pred_opti_data!C3)*loans_pred_opti_data!D3 -> 14.691005 | E3: Objective - Total Revenue
A4: 0 | B4: =loans_pred_opti_data!D4*loans_pred_opti_data!B4 -> -73.330734 | C4: =(loans_pred_opti_data!B4-ret_PESS!$G$35*loans_pred_opti_data!C4)*loans_pred_opti_data!D4 -> -232.96425 | E4: =SUMPRODUCT(A2:A2001,B2:B2001) -> 41174.406
A5: 0 | B5: =loans_pred_opti_data!D5*loans_pred_opti_data!B5 -> 299.32261 | C5: =(loans_pred_opti_data!B5-ret_PESS!$G$35*loans_pred_opti_data!C5)*loans_pred_opti_data!D5 -> 224.34837
A6: 0 | B6: =loans_pred_opti_data!D6*loans_pred_opti_data!B6 -> 29.668493 | C6: =(loans_pred_opti_data!B6-ret_PESS!$G$35*loans_pred_opti_data!C6)*loans_pred_opti_data!D6 -> -2.9351755
A7: 0 | B7: =loans_pred_opti_data!D7*loans_pred_opti_data!B7 -> 1083.6965 | C7: =(loans_pred_opti_data!B7-ret_PESS!$G$35*loans_pred_opti_data!C7)*loans_pred_opti_data!D7 -> 827.39249 | E7: Constraint LHS's | F7: Constraint Type | G7: Constraint RHS's
A8: 0 | B8: =loans_pred_opti_data!D8*loans_pred_opti_data!B8 -> 186.38834 | C8: =(loans_pred_opti_data!B8-ret_PESS!$G$35*loans_pred_opti_data!C8)*loans_pred_opti_data!D8 -> 144.00357
A9: 0 | B9: =loans_pred_opti_data!D9*loans_pred_opti_data!B9 -> 362.60197 | C9: =(loans_pred_opti_data!B9-ret_PESS!$G$35*loans_pred_opti_data!C9)*loans_pred_opti_data!D9 -> 272.63289 | E9: Budget Usage | G9: Budget
A10: 0 | B10: =loans_pred_opti_data!D10*loans_pred_opti_data!B10 -> 130.96183 | C10: =(loans_pred_opti_data!B10-ret_PESS!$G$35*loans_pred_opti_data!C10)*loans_pred_opti_data!D10 -> 93.474709 | E10: =SUMPRODUCT(A2:A2001,loans_pred_opti_data!D2:D2001) -> 1964675 | F10: <= | G10: 500000
A11: 0 | B11: =loans_pred_opti_data!D11*loans_pred_opti_data!B11 -> 191.44759 | C11: =(loans_pred_opti_data!B11-ret_PESS!$G$35*loans_pred_opti_data!C11)*loans_pred_opti_data!D11 -> 108.03875
A12: 0 | B12: =loans_pred_opti_data!D12*loans_pred_opti_data!B12 -> 549.35756 | C12: =(loans_pred_opti_data!B12-ret_PESS!$G$35*loans_pred_opti_data!C12)*loans_pred_opti_data!D12 -> 386.33922 | E12: Total Loans Picked | G12: Max Loan Count
A13: 0 | B13: =loans_pred_opti_data!D13*loans_pred_opti_data!B13 -> 818.31444 | C13: =(loans_pred_opti_data!B13-ret_PESS!$G$35*loans_pred_opti_data!C13)*loans_pred_opti_data!D13 -> 631.75734 | E13: =SUM(A2:A2001) -> 136 | F13: <= | G13: 150
A14: 0 | B14: =loans_pred_opti_data!D14*loans_pred_opti_data!B14 -> 623.8103 | C14: =(loans_pred_opti_data!B14-ret_PESS!$G$35*loans_pred_opti_data!C14)*loans_pred_opti_data!D14 -> 525.63121 | G14: Min Loan Count
A15: 1 | B15: =loans_pred_opti_data!D15*loans_pred_opti_data!B15 -> 168.07338 | C15: =(loans_pred_opti_data!B15-ret_PESS!$G$35*loans_pred_opti_data!C15)*loans_pred_opti_data!D15 -> 114.07355 | F15: >= | G15: =0.9*G13 -> 135
A16: 0 | B16: =loans_pred_opti_data!D16*loans_pred_opti_data!B16 -> 256.49986 | C16: =(loans_pred_opti_data!B16-ret_PESS!$G$35*loans_pred_opti_data!C16)*loans_pred_opti_data!D16 -> 181.52562
A17: 1 | B17: =loans_pred_opti_data!D17*loans_pred_opti_data!B17 -> 12.237247 | C17: =(loans_pred_opti_data!B17-ret_PESS!$G$35*loans_pred_opti_data!C17)*loans_pred_opti_data!D17 -> -157.36011
A18: 0 | B18: =loans_pred_opti_data!D18*loans_pred_opti_data!B18 -> -14.201806 | C18: =(loans_pred_opti_data!B18-ret_PESS!$G$35*loans_pred_opti_data!C18)*loans_pred_opti_data!D18 -> -266.05389
A19: 0 | B19: =loans_pred_opti_data!D19*loans_pred_opti_data!B19 -> 301.3491 | C19: =(loans_pred_opti_data!B19-ret_PESS!$G$35*loans_pred_opti_data!C19)*loans_pred_opti_data!D19 -> 226.37486 | E19: Multiple Knapsack Model
A20: 0 | B20: =loans_pred_opti_data!D20*loans_pred_opti_data!B20 -> 193.23584 | C20: =(loans_pred_opti_data!B20-ret_PESS!$G$35*loans_pred_opti_data!C20)*loans_pred_opti_data!D20 -> 111.72667
A21: 0 | B21: =loans_pred_opti_data!D21*loans_pred_opti_data!B21 -> -47.640197 | C21: =(loans_pred_opti_data!B21-ret_PESS!$G$35*loans_pred_opti_data!C21)*loans_pred_opti_data!D21 -> -154.62099 | E21: Use simple knapsack model + the following
A22: 0 | B22: =loans_pred_opti_data!D22*loans_pred_opti_data!B22 -> 207.40086 | C22: =(loans_pred_opti_data!B22-ret_PESS!$G$35*loans_pred_opti_data!C22)*loans_pred_opti_data!D22 -> 125.89169
A23: 0 | B23: =loans_pred_opti_data!D23*loans_pred_opti_data!B23 -> 223.31866 | C23: =(loans_pred_opti_data!B23-ret_PESS!$G$35*loans_pred_opti_data!C23)*loans_pred_opti_data!D23 -> -73.476722 | E23: Constraint LHS's | F23: Constraint Type | G23: Constraint RHS's
A24: 0 | B24: =loans_pred_opti_data!D24*loans_pred_opti_data!B24 -> 72.005243 | C24: =(loans_pred_opti_data!B24-ret_PESS!$G$35*loans_pred_opti_data!C24)*loans_pred_opti_data!D24 -> -220.33821
A25: 0 | B25: =loans_pred_opti_data!D25*loans_pred_opti_data!B25 -> 280.11037 | C25: =(loans_pred_opti_data!B25-ret_PESS!$G$35*loans_pred_opti_data!C25)*loans_pred_opti_data!D25 -> 214.90303 | E25: Total Risk | G25: Risk Budget
A26: 0 | B26: =loans_pred_opti_data!D26*loans_pred_opti_data!B26 -> 92.144725 | C26: =(loans_pred_opti_data!B26-ret_PESS!$G$35*loans_pred_opti_data!C26)*loans_pred_opti_data!D26 -> -41.530317 | E26: =SUMPRODUCT(A2:A2001,loans_pred_opti_data!C2:C2001) -> 10.272721 | F26: <= | G26: 20
A27: 0 | B27: =loans_pred_opti_data!D27*loans_pred_opti_data!B27 -> 102.48359 | C27: =(loans_pred_opti_data!B27-ret_PESS!$G$35*loans_pred_opti_data!C27)*loans_pred_opti_data!D27 -> -134.95272
A28: 0 | B28: =loans_pred_opti_data!D28*loans_pred_opti_data!B28 -> 145.97795 | C28: =(loans_pred_opti_data!B28-ret_PESS!$G$35*loans_pred_opti_data!C28)*loans_pred_opti_data!D28 -> 93.495978
A29: 0 | B29: =loans_pred_opti_data!D29*loans_pred_opti_data!B29 -> 355.50463 | C29: =(loans_pred_opti_data!B29-ret_PESS!$G$35*loans_pred_opti_data!C29)*loans_pred_opti_data!D29 -> 273.99546
A30: 0 | B30: =loans_pred_opti_data!D30*loans_pred_opti_data!B30 -> 289.57379 | C30: =(loans_pred_opti_data!B30-ret_PESS!$G$35*loans_pred_opti_data!C30)*loans_pred_opti_data!D30 -> 208.06462 | E30: Markowitz Model
A31: 0 | B31: =loans_pred_opti_data!D31*loans_pred_opti_data!B31 -> 343.41414 | C31: =(loans_pred_opti_data!B31-ret_PESS!$G$35*loans_pred_opti_data!C31)*loans_pred_opti_data!D31 -> 253.44505
A32: 0 | B32: =loans_pred_opti_data!D32*loans_pred_opti_data!B32 -> 171.70619 | C32: =(loans_pred_opti_data!B32-ret_PESS!$G$35*loans_pred_opti_data!C32)*loans_pred_opti_data!D32 -> 126.72165 | E32: Use simple knapsack constraints + the following objective
A33: 0 | B33: =loans_pred_opti_data!D33*loans_pred_opti_data!B33 -> 18.024987 | C33: =(loans_pred_opti_data!B33-ret_PESS!$G$35*loans_pred_opti_data!C33)*loans_pred_opti_data!D33 -> -185.49185
A34: 1 | B34: =loans_pred_opti_data!D34*loans_pred_opti_data!B34 -> 200.61288 | C34: =(loans_pred_opti_data!B34-ret_PESS!$G$35*loans_pred_opti_data!C34)*loans_pred_opti_data!D34 -> 140.63349 | E34: Markowitz Objective | G34: Sensitivity Parameter
A35: 0 | B35: =loans_pred_opti_data!D35*loans_pred_opti_data!B35 -> 241.92684 | C35: =(loans_pred_opti_data!B35-ret_PESS!$G$35*loans_pred_opti_data!C35)*loans_pred_opti_data!D35 -> 144.11583 | E35: =SUMPRODUCT(A2:A2001,C2:C2001) -> 26506.095 | G35: 0.1
A36: 0 | B36: =loans_pred_opti_data!D36*loans_pred_opti_data!B36 -> 34.601455 | C36: =(loans_pred_opti_data!B36-ret_PESS!$G$35*loans_pred_opti_data!C36)*loans_pred_opti_data!D36 -> 24.820355
A37: 0 | B37: =loans_pred_opti_data!D37*loans_pred_opti_data!B37 -> 386.43921 | C37: =(loans_pred_opti_data!B37-ret_PESS!$G$35*loans_pred_opti_data!C37)*loans_pred_opti_data!D37 -> 309.38503
A38: 0 | B38: =loans_pred_opti_data!D38*loans_pred_opti_data!B38 -> 257.56006 | C38: =(loans_pred_opti_data!B38-ret_PESS!$G$35*loans_pred_opti_data!C38)*loans_pred_opti_data!D38 -> 197.58067
A39: 0 | B39: =loans_pred_opti_data!D39*loans_pred_opti_data!B39 -> 468.54324 | C39: =(loans_pred_opti_data!B39-ret_PESS!$G$35*loans_pred_opti_data!C39)*loans_pred_opti_data!D39 -> 361.33008
A40: 0 | B40: =loans_pred_opti_data!D40*loans_pred_opti_data!B40 -> 296.75062 | C40: =(loans_pred_opti_data!B40-ret_PESS!$G$35*loans_pred_opti_data!C40)*loans_pred_opti_data!D40 -> 214.88056
...
